Sending request to http://localhost:8000/askLLM with data: {"text": "what is BASS", "use_llm": true}
Error: HTTPConnectionPool(host='localhost', port=8000): Max retries exceeded with url: /askLLM (Caused by NewConnectionError('<urllib3.connection.HTTPConnection object at 0x10245ff90>: Failed to establish a new connection: [Errno 61] Connection refused'))
Traceback (most recent call last):
  File "/Users/csbrar/service-center-chat/venv/lib/python3.11/site-packages/urllib3/connection.py", line 198, in _new_conn
    sock = connection.create_connection(
           ^^^^^^^^^^^^^^^^^^^^^^^^^^^^^
  File "/Users/csbrar/service-center-chat/venv/lib/python3.11/site-packages/urllib3/util/connection.py", line 85, in create_connection
    raise err
  File "/Users/csbrar/service-center-chat/venv/lib/python3.11/site-packages/urllib3/util/connection.py", line 73, in create_connection
    sock.connect(sa)
ConnectionRefusedError: [Errno 61] Connection refused

The above exception was the direct cause of the following exception:

Traceback (most recent call last):
  File "/Users/csbrar/service-center-chat/venv/lib/python3.11/site-packages/urllib3/connectionpool.py", line 787, in urlopen
    response = self._make_request(
               ^^^^^^^^^^^^^^^^^^^
  File "/Users/csbrar/service-center-chat/venv/lib/python3.11/site-packages/urllib3/connectionpool.py", line 493, in _make_request
    conn.request(
  File "/Users/csbrar/service-center-chat/venv/lib/python3.11/site-packages/urllib3/connection.py", line 445, in request
    self.endheaders()
  File "/Users/csbrar/anaconda3/lib/python3.11/http/client.py", line 1298, in endheaders
    self._send_output(message_body, encode_chunked=encode_chunked)
  File "/Users/csbrar/anaconda3/lib/python3.11/http/client.py", line 1058, in _send_output
    self.send(msg)
  File "/Users/csbrar/anaconda3/lib/python3.11/http/client.py", line 996, in send
    self.connect()
  File "/Users/csbrar/service-center-chat/venv/lib/python3.11/site-packages/urllib3/connection.py", line 276, in connect
    self.sock = self._new_conn()
                ^^^^^^^^^^^^^^^^
  File "/Users/csbrar/service-center-chat/venv/lib/python3.11/site-packages/urllib3/connection.py", line 213, in _new_conn
    raise NewConnectionError(
urllib3.exceptions.NewConnectionError: <urllib3.connection.HTTPConnection object at 0x10245ff90>: Failed to establish a new connection: [Errno 61] Connection refused

The above exception was the direct cause of the following exception:

Traceback (most recent call last):
  File "/Users/csbrar/service-center-chat/venv/lib/python3.11/site-packages/requests/adapters.py", line 667, in send
    resp = conn.urlopen(
           ^^^^^^^^^^^^^
  File "/Users/csbrar/service-center-chat/venv/lib/python3.11/site-packages/urllib3/connectionpool.py", line 841, in urlopen
    retries = retries.increment(
              ^^^^^^^^^^^^^^^^^^
  File "/Users/csbrar/service-center-chat/venv/lib/python3.11/site-packages/urllib3/util/retry.py", line 519, in increment
    raise MaxRetryError(_pool, url, reason) from reason  # type: ignore[arg-type]
    ^^^^^^^^^^^^^^^^^^^^^^^^^^^^^^^^^^^^^^^^^^^^^^^^^^^
urllib3.exceptions.MaxRetryError: HTTPConnectionPool(host='localhost', port=8000): Max retries exceeded with url: /askLLM (Caused by NewConnectionError('<urllib3.connection.HTTPConnection object at 0x10245ff90>: Failed to establish a new connection: [Errno 61] Connection refused'))

During handling of the above exception, another exception occurred:

Traceback (most recent call last):
  File "/Users/csbrar/service-center-chat/test_api_bass.py", line 19, in test_api_bass
    response = requests.post(url, json=data)
               ^^^^^^^^^^^^^^^^^^^^^^^^^^^^^
  File "/Users/csbrar/service-center-chat/venv/lib/python3.11/site-packages/requests/api.py", line 115, in post
    return request("post", url, data=data, json=json, **kwargs)
           ^^^^^^^^^^^^^^^^^^^^^^^^^^^^^^^^^^^^^^^^^^^^^^^^^^^^
  File "/Users/csbrar/service-center-chat/venv/lib/python3.11/site-packages/requests/api.py", line 59, in request
    return session.request(method=method, url=url, **kwargs)
           ^^^^^^^^^^^^^^^^^^^^^^^^^^^^^^^^^^^^^^^^^^^^^^^^^
  File "/Users/csbrar/service-center-chat/venv/lib/python3.11/site-packages/requests/sessions.py", line 589, in request
    resp = self.send(prep, **send_kwargs)
           ^^^^^^^^^^^^^^^^^^^^^^^^^^^^^^
  File "/Users/csbrar/service-center-chat/venv/lib/python3.11/site-packages/requests/sessions.py", line 703, in send
    r = adapter.send(request, **kwargs)
        ^^^^^^^^^^^^^^^^^^^^^^^^^^^^^^^
  File "/Users/csbrar/service-center-chat/venv/lib/python3.11/site-packages/requests/adapters.py", line 700, in send
    raise ConnectionError(e, request=request)
requests.exceptions.ConnectionError: HTTPConnectionPool(host='localhost', port=8000): Max retries exceeded with url: /askLLM (Caused by NewConnectionError('<urllib3.connection.HTTPConnection object at 0x10245ff90>: Failed to establish a new connection: [Errno 61] Connection refused'))


Test failed
